Workbook

Sheet README
A1: G1 economics model v2 - Borut, Bomet. Rebuilt 2026-10-15 from owner intake update 2. v1 is kept as G1-model-v1.xlsx. All amounts KES; USD at CBK rate on Inputs.
A2: Low = adverse case, Base, High = favourable. Every calculated cell is a live formula; change blue cells on Inputs (or Overhead).
A3: Tags: SOURCED (published figure with URL), BENCHMARK (published but undated/other area, or standard convention), ASSUMED (no source), OWNER-REPORTED (supplied by owner; no documents seen).
A4: Sheets: Inputs > Cattle, Sheep, Goats, Poultry (one block per breed/species), Mix, Labour, Lorry, Capital, Overhead > Farm_PnL > Cash_18m > B12 > Breakeven > Scenarios > Collect_8wk.
A5: Changes from v1: poultry 2,270 birds by breed (v1 ~1,000; intake file shows 2,770 which is an arithmetic error: 4 x 500 + 270 = 2,270); 23 acres, no rent or rates; staff 3 x 22,000; weekly vet; lorry; structures KES 2m; 6-month stores; owner >300 km.
A6: Land has no cash cost. B12 charges no land rent; its opportunity cost appears through lease rent, sale proceeds and g x L, as the PLAN convention requires.
A7: No farm accounts exist. This is a benchmark screen, not a forecast. Crops (and tea) are not modelled. Lorry hire income is zero in all headline cases.
A8: Stress limit gate uses literal B12 cash basis (depreciation added back); the v1 basis (OMBM) is shown as a memo on B12.
A10: Input counts by tag (live):
A11: SOURCED | B11: =COUNTIF(Inputs!$F$3:$F$306,"SOURCED") -> 8
A12: BENCHMARK | B12: =COUNTIF(Inputs!$F$3:$F$306,"BENCHMARK") -> 40
A13: ASSUMED | B13: =COUNTIF(Inputs!$F$3:$F$306,"ASSUMED") -> 217
A14: OWNER-REPORTED | B14: =COUNTIF(Inputs!$F$3:$F$306,"OWNER-REPORTED") -> 19
A15: Total inputs | B15: =SUM(B11:B14) -> 284
A16: Poultry check: standing birds (should be 2,270) | B16: =Poultry!D244 -> 2270
A17: Poultry slot-margin check (should be 0) | B17: =Poultry!D263 -> 0

Sheet Scenarios
A1: Scenario summary: Low (adverse) / Base / High (favourable). KES with USD for base. Poultry corrected to 2,270 birds.
A2: Line | B2: Unit | C2: Low (adverse) | D2: Base | E2: High (favourable) | F2: Base in USD | G2: Note
A3: Revenue and margin
A4: Revenue | B4: KES | C4: =Farm_PnL!C15 -> 3249336 | D4: =Farm_PnL!D15 -> 4854130 | E4: =Farm_PnL!E15 -> 6996262.8 | F4: =D4/Inputs!$D$4 -> 37371.083
A5: Variable costs | B5: KES | C5: =Farm_PnL!C31 -> 5011545.2 | D5: =Farm_PnL!D31 -> 4035305.2 | E5: =Farm_PnL!E31 -> 3404828 | F5: =D5/Inputs!$D$4 -> 31067.097
A6: Gross margin | B6: KES | C6: =Farm_PnL!C30 -> -1762209.2 | D6: =Farm_PnL!D30 -> 818824.81 | E6: =Farm_PnL!E30 -> 3591434.8 | F6: =D6/Inputs!$D$4 -> 6303.9865
A7: Hired labour (3 x 22,000 + statutory + casuals) | B7: KES | C7: =Farm_PnL!C33 -> 911684.38 | D7: =Farm_PnL!D33 -> 868200 | E7: =Farm_PnL!E33 -> 865700 | F7: =D7/Inputs!$D$4 -> 6684.1173
A8: Weekly vet fees | B8: KES | C8: =Farm_PnL!C34 -> 208000 | D8: =Farm_PnL!D34 -> 156000 | E8: =Farm_PnL!E34 -> 104000 | F8: =D8/Inputs!$D$4 -> 1201.0162
A9: Lorry net cost (incl. depreciation) | B9: KES | C9: =Farm_PnL!C43 -> 1384475 | D9: =Farm_PnL!D43 -> 949433.33 | E9: =Farm_PnL!E43 -> 691622.73 | F9: =D9/Inputs!$D$4 -> 7309.5183
A10: Labour + fixed costs (all) | B10: KES | C10: =Farm_PnL!C44 -> 2919159.4 | D10: =Farm_PnL!D44 -> 2351633.3 | E10: =Farm_PnL!E44 -> 2001322.7 | F10: =D10/Inputs!$D$4 -> 18104.807
A11: OMBM (lorry as owned) | B11: KES | C11: =Farm_PnL!C46 -> -4681368.6 | D11: =Farm_PnL!D46 -> -1532808.5 | E11: =Farm_PnL!E46 -> 1590112.1 | F11: =D11/Inputs!$D$4 -> -11800.82
A12: OMBM % of revenue | B12: % | C12: =Farm_PnL!C47 -> -1.4407155 | D12: =Farm_PnL!D47 -> -0.3157741 | E12: =Farm_PnL!E47 -> 0.22728021
A13: OMBM if there were no lorry | B13: KES | C13: =Farm_PnL!C48 -> -3296893.6 | D13: =Farm_PnL!D48 -> -583375.19 | E13: =Farm_PnL!E48 -> 2281734.8 | F13: =D13/Inputs!$D$4 -> -4491.3018
A14: Cash margin (before controls) | B14: KES | C14: =Farm_PnL!C49 -> -4059493.6 | D14: =Farm_PnL!D49 -> -995308.52 | E14: =Farm_PnL!E49 -> 2071362.1 | F14: =D14/Inputs!$D$4 -> -7662.7032
A15: Cash margin after controls, stipend and owner travel | B15: KES | C15: =Farm_PnL!C49-B12!C17-B12!C18-B12!C19 -> -4559493.6 | D15: =Farm_PnL!D49-B12!D17-B12!D18-B12!D19 -> -1351308.5 | E15: =Farm_PnL!E49-B12!E17-B12!E18-B12!E19 -> 1763362.1 | F15: =D15/Inputs!$D$4 -> -10403.484
A16: v1 comparison (static values from G1-model-v1.xlsx; v1 had 1,000 birds, 12 acres, KES 533k labour)
A17: v1 revenue | B17: KES | C17: 2158161.9 | D17: 2776511.8 | E17: 3568790
A18: v1 gross margin | B18: KES | C18: -387335.25 | D18: 527232.23 | E18: 1517089.9
A19: v1 hired labour | B19: KES | C19: 535300 | D19: 532800 | E19: 530300
A20: v1 OMBM | B20: KES | C20: -1175635.2 | D20: -233567.77 | E20: 784789.85
A21: v1 owner-operator B12 value | B21: KES | C21: -1894395.2 | D21: -710748.56 | E21: 511654.85
A22: Gross margin by enterprise
A23: Cattle and dairy | B23: KES | C23: =Farm_PnL!C19 -> -63160 | D23: =Farm_PnL!D19 -> 107600 | E23: =Farm_PnL!E19 -> 329400 | F23: =D23/Inputs!$D$4 -> 828.39326
A24: Sheep | B24: KES | C24: =Farm_PnL!C20 -> 17179.04 | D24: =Farm_PnL!D20 -> 119340.8 | E24: =Farm_PnL!E20 -> 255260.48 | F24: =D24/Inputs!$D$4 -> 918.78359
A25: Goats | B25: KES | C25: =Farm_PnL!C21 -> 17532.8 | D25: =Farm_PnL!D21 -> 39904 | E25: =Farm_PnL!E21 -> 69280.336 | F25: =D25/Inputs!$D$4 -> 307.2138
A26: Sasso | B26: KES | C26: =Farm_PnL!C22 -> -427996.43 | D26: =Farm_PnL!D22 -> 86169.503 | E26: =Farm_PnL!E22 -> 600246.61 | F26: =D26/Inputs!$D$4 -> 663.40367
A27: Kuroiler | B27: KES | C27: =Farm_PnL!C23 -> -427996.43 | D27: =Farm_PnL!D23 -> 86169.503 | E27: =Farm_PnL!E23 -> 600246.61 | F27: =D27/Inputs!$D$4 -> 663.40367
A28: Rainbow | B28: KES | C28: =Farm_PnL!C24 -> -427996.43 | D28: =Farm_PnL!D24 -> 86169.503 | E28: =Farm_PnL!E24 -> 600246.61 | F28: =D28/Inputs!$D$4 -> 663.40367
A29: Kebro | B29: KES | C29: =Farm_PnL!C25 -> -427996.43 | D29: =Farm_PnL!D25 -> 86169.503 | E29: =Farm_PnL!E25 -> 600246.61 | F29: =D29/Inputs!$D$4 -> 663.40367
A30: Ducks | B30: KES | C30: =Farm_PnL!C26 -> -26320 | D30: =Farm_PnL!D26 -> 45560 | E30: =Farm_PnL!E26 -> 147613.14 | F30: =D30/Inputs!$D$4 -> 350.75833
A31: Geese | B31: KES | C31: =Farm_PnL!C27 -> 11471.429 | D31: =Farm_PnL!D27 -> 65622 | E31: =Farm_PnL!E27 -> 133068.57 | F31: =D31/Inputs!$D$4 -> 505.2121
A32: Turkeys | B32: KES | C32: =Farm_PnL!C28 -> 3454.2857 | D32: =Farm_PnL!D28 -> 36030 | E32: =Farm_PnL!E28 -> 72258 | F32: =D32/Inputs!$D$4 -> 277.38856
A33: Guinea fowl | B33: KES | C33: =Farm_PnL!C29 -> -10381.071 | D33: =Farm_PnL!D29 -> 60090 | E33: =Farm_PnL!E29 -> 183567.86 | F33: =D33/Inputs!$D$4 -> 462.62222
A34: Gross margin per task hour
A35: Cattle and dairy | B35: KES/h | C35: =Farm_PnL!C52 -> -43.260274 | D35: =Farm_PnL!D52 -> 84.227006 | E35: =Farm_PnL!E52 -> 282.02055
A36: Sheep | B36: KES/h | C36: =Farm_PnL!C53 -> 26.147702 | D36: =Farm_PnL!D53 -> 217.97406 | E36: =Farm_PnL!E53 -> 537.95675
A37: Goats | B37: KES/h | C37: =Farm_PnL!C54 -> 80.058447 | D37: =Farm_PnL!D54 -> 218.65205 | E37: =Farm_PnL!E54 -> 421.79809
A38: Four chicken breeds | B38: KES/h | C38: =Farm_PnL!C55 -> -469.03718 | D38: =Farm_PnL!D55 -> 118.04042 | E38: =Farm_PnL!E55 -> 996.6735
A39: Ducks, geese, turkeys, guinea fowl | B39: KES/h | C39: =Farm_PnL!C56 -> -44.191491 | D39: =Farm_PnL!D56 -> 525.88026 | E39: =Farm_PnL!E56 -> 1649.7012
A40: Poultry volumes
...

Sheet Inputs
A1: INPUTS - KES unless stated. Blue = editable input. Tags: SOURCED / BENCHMARK / ASSUMED / OWNER-REPORTED. Low = adverse, High = favourable.
A2: Parameter | B2: Unit | C2: Low (adverse) | D2: Base | E2: High (favourable) | F2: Tag | G2: Source / note (accessed 2026-10-15 unless stated)
A3: General
A4: Exchange rate | B4: KES per USD | C4: 129.89 | D4: 129.89 | E4: 129.89 | F4: SOURCED | G4: CBK indicative rate posted 7 Oct 2026 (centralbank.go.ke via web search; confirm daily rate). Unchanged from v1
A5: Declared real return on cash proceeds | B5: % p.a. | C5: 0.02 | D5: 0.02 | E5: 0.02 | F5: ASSUMED | G5: B12 default 2%
A6: Real change in land value g | B6: % p.a. | C6: 0 | D6: 0.01 | E6: 0.02 | F6: ASSUMED | G6: B12 default +1%; no local land-value series found
A7: Risk charge on capital at risk | B7: % | C7: 0.05 | D7: 0.04 | E7: 0.03 | F7: BENCHMARK | G7: B12 default 3-5%
A8: Owner hourly shadow price p | B8: KES/h | C8: 400 | D8: 300 | E8: 250 | F8: ASSUMED | G8: Owner's occupation unknown. Test sensitivity
A9: Selling cost + tax on sale | B9: % | C9: 0.05 | D9: 0.05 | E9: 0.05 | F9: BENCHMARK | G9: B12 default 5%; accountant to quantify
A10: Land, structures, water (owner intake update 2)
A11: Farm area | B11: acres | C11: 23 | D11: 23 | E11: 23 | F11: OWNER-REPORTED | G11: Intake update 2: 23 acres, altitude 1,765-1,790 m. v1 guessed 12. No documents seen
A12: Land value per acre (opportunity cost / sale value, NOT a cash cost) | B12: KES/acre | C12: 350000 | D12: 500000 | E12: 700000 | F12: ASSUMED | G12: No Bomet price found again in v2 search. Only a low-authority blog (graduatefarmer.co.ke, 2025) gives 150k remote to 800k+ near Nairobi/main roads. Unchanged from v1; get a valuer figure
A13: Farm structures, replacement value (houses, stores, fencing, equipment) | B13: KES | C13: 2000000 | D13: 2000000 | E13: 2000000 | F13: OWNER-REPORTED | G13: Owner: structures "valued at about KES 2m". AMBIGUOUS whether this is structures only or total capital. Capital sheet shows 2m cannot be total (animals alone exceed it). Treated as structures only
A14: Depreciation life of structures | B14: years | C14: 10 | D14: 10 | E14: 10 | F14: ASSUMED | G14: Unchanged from v1. Mixed timber/iron-sheet/block structures likely 10-20 years
A15: Repairs and maintenance | B15: % of structures | C15: 0.04 | D15: 0.03 | E15: 0.02 | F15: ASSUMED | G15: Unchanged from v1
A16: Land rent and county land rates | B16: KES/yr | C16: 0 | D16: 0 | E16: 0 | F16: OWNER-REPORTED | G16: Owner: no land rent or rates payable. Land has opportunity cost only (see B12: lease rent, sale proceeds, g x L)
A17: Water pans: separate value counted in asset base | B17: KES | C17: 0 | D17: 0 | E17: 0 | F17: ASSUMED | G17: Pans are sunk earthworks; treated as part of the land value to avoid double counting. Owner says "about 8m litres" each: ambiguous (8 million L = 8,000 m3 or 8 m3). Strong water security reported; upkeep inside Water line below
A18: Lease/sale legally executable now? (1 yes, 0 no/unknown) | B18: flag | C18: 0 | D18: 0 | E18: 0 | F18: ASSUMED | G18: Land searchers confirmed ownership (owner-reported) but title document, freehold status and any Land Control Board consent not seen. 0 keeps lease/sale out of Ranking B; set 1 once a lawyer confirms
A19: Herd (owner intake; counts confirmed by owner-reported independent count)
A20: Cattle | B20: head | C20: 10 | D20: 10 | E20: 10 | F20: OWNER-REPORTED | G20: Intake update 2 (who counted and when not stated)
A21: Sheep (tagged) | B21: head | C21: 50 | D21: 50 | E21: 50 | F21: OWNER-REPORTED | G21: Intake update 2
A22: Goats | B22: head | C22: 10 | D22: 10 | E22: 10 | F22: OWNER-REPORTED | G22: Intake update 2
A23: TLU factor cattle | B23: TLU/head | C23: 0.7 | D23: 0.7 | E23: 0.7 | F23: BENCHMARK | G23: Standard convention
A24: TLU factor sheep/goat | B24: TLU/head | C24: 0.1 | D24: 0.1 | E24: 0.1 | F24: BENCHMARK | G24: Standard convention
A25: TLU factor poultry | B25: TLU/bird | C25: 0.01 | D25: 0.01 | E25: 0.01 | F25: BENCHMARK | G25: Standard convention
A26: Cattle (assumed dairy-type, 4 cows in milk of 10 head; unchanged from v1)
A27: Cows in milk | B27: head | C27: 4 | D27: 4 | E27: 5 | F27: ASSUMED | G27: Herd structure unknown
A28: Milk per cow per day | B28: L | C28: 7 | D28: 8 | E28: 9 | F28: ASSUMED | G28: Measure
A29: Days in milk per year per cow | B29: days | C29: 290 | D29: 300 | E29: 305 | F29: ASSUMED
A30: Farm-gate milk price | B30: KES/L | C30: 34 | D30: 38 | E30: 42 | F30: BENCHMARK | G30: Brookside/New KCC ~37 (Business Daily, undated); KCC Sotik 41-43 (KNA). Dates unconfirmed
A31: Cooling, transport, levies | B31: KES/L | C31: 3 | D31: 2.5 | E31: 2 | F31: ASSUMED
A32: Dairy meal per cow in milk per day | B32: kg | C32: 3 | D32: 3 | E32: 3 | F32: ASSUMED
A33: Dairy meal price | B33: KES/kg | C33: 56 | D33: 52 | E33: 48 | F33: BENCHMARK | G33: Derived from layers mash 3,900/70 kg (Capital FM Nov 25)
A34: Purchased hay/forage per head | B34: KES/head/yr | C34: 4000 | D34: 3000 | E34: 2000 | F34: ASSUMED | G34: Depends on own fodder; 23 acres may allow more own fodder than v1 assumed 12
A35: Minerals and salt per head | B35: KES/head/yr | C35: 1800 | D35: 1800 | E35: 1800 | F35: ASSUMED
A36: Drugs, AI, acaricide per head (excl. weekly vet visit fee) | B36: KES/head/yr | C36: 7000 | D36: 6000 | E36: 5000 | F36: ASSUMED | G36: Replace with vet quote
A37: Cattle sold per year | B37: head | C37: 1 | D37: 2 | E37: 2 | F37: ASSUMED
A38: Price per head sold | B38: KES | C38: 32000 | D38: 40000 | E38: 50000 | F38: BENCHMARK | G38: KMC 140-180 KES/kg live (kenyanews.go.ke Feb 2026) x ~250 kg
A39: Mortality/loss | B39: % of herd value | C39: 0.04 | D39: 0.03 | E39: 0.02 | F39: ASSUMED
A40: Value per head (capital) | B40: KES | C40: 60000 | D40: 60000 | E40: 60000 | F40: ASSUMED
...

Sheet Cattle
A1: Cattle (annual, KES). All cells are live formulas from Inputs.
A2: Line | B2: Unit | C2: Low (adverse) | D2: Base | E2: High (favourable) | F2: Base in USD | G2: Note
A3: Production
A4: Milk sold | B4: L/yr | C4: =Inputs!C27*Inputs!C28*Inputs!C29 -> 8120 | D4: =Inputs!D27*Inputs!D28*Inputs!D29 -> 9600 | E4: =Inputs!E27*Inputs!E28*Inputs!E29 -> 13725
A5: Revenue
A6: Milk revenue | B6: KES | C6: =C4*Inputs!C30 -> 276080 | D6: =D4*Inputs!D30 -> 364800 | E6: =E4*Inputs!E30 -> 576450 | F6: =D6/Inputs!$D$4 -> 2808.5303
A7: Cattle sales | B7: KES | C7: =Inputs!C37*Inputs!C38 -> 32000 | D7: =Inputs!D37*Inputs!D38 -> 80000 | E7: =Inputs!E37*Inputs!E38 -> 100000 | F7: =D7/Inputs!$D$4 -> 615.90577
A8: Total revenue | B8: KES | C8: =C6+C7 -> 308080 | D8: =D6+D7 -> 444800 | E8: =E6+E7 -> 676450 | F8: =D8/Inputs!$D$4 -> 3424.4361
A9: Variable costs
A10: Dairy meal | B10: KES | C10: =Inputs!C27*Inputs!C32*Inputs!C29*Inputs!C33 -> 194880 | D10: =Inputs!D27*Inputs!D32*Inputs!D29*Inputs!D33 -> 187200 | E10: =Inputs!E27*Inputs!E32*Inputs!E29*Inputs!E33 -> 219600 | F10: =D10/Inputs!$D$4 -> 1441.2195
A11: Purchased forage | B11: KES | C11: =Inputs!C20*Inputs!C34 -> 40000 | D11: =Inputs!D20*Inputs!D34 -> 30000 | E11: =Inputs!E20*Inputs!E34 -> 20000 | F11: =D11/Inputs!$D$4 -> 230.96466
A12: Minerals | B12: KES | C12: =Inputs!C20*Inputs!C35 -> 18000 | D12: =Inputs!D20*Inputs!D35 -> 18000 | E12: =Inputs!E20*Inputs!E35 -> 18000 | F12: =D12/Inputs!$D$4 -> 138.5788
A13: Drugs, AI, acaricide | B13: KES | C13: =Inputs!C20*Inputs!C36 -> 70000 | D13: =Inputs!D20*Inputs!D36 -> 60000 | E13: =Inputs!E20*Inputs!E36 -> 50000 | F13: =D13/Inputs!$D$4 -> 461.92932
A14: Milk cooling, transport, levies | B14: KES | C14: =C4*Inputs!C31 -> 24360 | D14: =D4*Inputs!D31 -> 24000 | E14: =E4*Inputs!E31 -> 27450 | F14: =D14/Inputs!$D$4 -> 184.77173
A15: Mortality/loss allowance | B15: KES | C15: =Inputs!C20*Inputs!C40*Inputs!C39 -> 24000 | D15: =Inputs!D20*Inputs!D40*Inputs!D39 -> 18000 | E15: =Inputs!E20*Inputs!E40*Inputs!E39 -> 12000 | F15: =D15/Inputs!$D$4 -> 138.5788
A16: Total variable costs | B16: KES | C16: =SUM(C10:C15) -> 371240 | D16: =SUM(D10:D15) -> 337200 | E16: =SUM(E10:E15) -> 347050 | F16: =D16/Inputs!$D$4 -> 2596.0428
A17: Gross margin (before labour and fixed costs) | B17: KES | C17: =C8-C16 -> -63160 | D17: =D8-D16 -> 107600 | E17: =E8-E16 -> 329400 | F17: =D17/Inputs!$D$4 -> 828.39326
A18: Gross margin per head | B18: KES/head | C18: =C17/Inputs!C20 -> -6316 | D18: =D17/Inputs!D20 -> 10760 | E18: =E17/Inputs!E20 -> 32940
A19: Stock capital | B19: KES | C19: =Inputs!C20*Inputs!C40 -> 600000 | D19: =Inputs!D20*Inputs!D40 -> 600000 | E19: =Inputs!E20*Inputs!E40 -> 600000 | F19: =D19/Inputs!$D$4 -> 4619.2932
A20: Memo: purchased feed and forage | B20: KES | C20: =C10+C11 -> 234880 | D20: =D10+D11 -> 217200 | E20: =E10+E11 -> 239600 | F20: =D20/Inputs!$D$4 -> 1672.1842
A21: Memo: drugs and vet inputs | B21: KES | C21: =C13 -> 70000 | D21: =D13 -> 60000 | E21: =E13 -> 50000 | F21: =D21/Inputs!$D$4 -> 461.92932

Sheet Sheep
A1: Sheep (annual, KES). All cells are live formulas from Inputs.
A2: Line | B2: Unit | C2: Low (adverse) | D2: Base | E2: High (favourable) | F2: Base in USD | G2: Note
A3: Production
A4: Lambs/hoggets sold (weaned less replacements) | B4: head | C4: =MAX(0,Inputs!C42*(Inputs!C43-Inputs!C44)) -> 24.8 | D4: =MAX(0,Inputs!D42*(Inputs!D43-Inputs!D44)) -> 34 | E4: =MAX(0,Inputs!E42*(Inputs!E43-Inputs!E44)) -> 43.2
A5: Sale price per head | B5: KES | C5: =Inputs!C45*Inputs!C46 -> 5670 | D5: =Inputs!D45*Inputs!D46 -> 6720 | E5: =Inputs!E45*Inputs!E46 -> 8120 | F5: =D5/Inputs!$D$4 -> 51.736084
A6: Revenue
A7: Sales revenue | B7: KES | C7: =C4*C5 -> 140616 | D7: =D4*D5 -> 228480 | E7: =E4*E5 -> 350784 | F7: =D7/Inputs!$D$4 -> 1759.0269
A8: Variable costs
A9: Supplement/feed | B9: KES | C9: =Inputs!C21*Inputs!C47 -> 60000 | D9: =Inputs!D21*Inputs!D47 -> 50000 | E9: =Inputs!E21*Inputs!E47 -> 40000 | F9: =D9/Inputs!$D$4 -> 384.9411
A10: Drugs, deworm, dip, vaccines | B10: KES | C10: =Inputs!C21*Inputs!C48 -> 45000 | D10: =Inputs!D21*Inputs!D48 -> 40000 | E10: =Inputs!E21*Inputs!E48 -> 35000 | F10: =D10/Inputs!$D$4 -> 307.95288
A11: Minerals | B11: KES | C11: =Inputs!C21*Inputs!C49 -> 10000 | D11: =Inputs!D21*Inputs!D49 -> 10000 | E11: =Inputs!E21*Inputs!E49 -> 10000 | F11: =D11/Inputs!$D$4 -> 76.988221
A12: Selling cost | B12: KES | C12: =C7*Inputs!C50 -> 8436.96 | D12: =D7*Inputs!D50 -> 9139.2 | E12: =E7*Inputs!E50 -> 10523.52 | F12: =D12/Inputs!$D$4 -> 70.361075
A13: Total variable costs | B13: KES | C13: =SUM(C9:C12) -> 123436.96 | D13: =SUM(D9:D12) -> 109139.2 | E13: =SUM(E9:E12) -> 95523.52 | F13: =D13/Inputs!$D$4 -> 840.24328
A14: Gross margin | B14: KES | C14: =C7-C13 -> 17179.04 | D14: =D7-D13 -> 119340.8 | E14: =E7-E13 -> 255260.48 | F14: =D14/Inputs!$D$4 -> 918.78359
A15: Gross margin per head | B15: KES/head | C15: =C14/Inputs!C21 -> 343.5808 | D15: =D14/Inputs!D21 -> 2386.816 | E15: =E14/Inputs!E21 -> 5105.2096
A16: Stock capital | B16: KES | C16: =Inputs!C21*Inputs!C51 -> 300000 | D16: =Inputs!D21*Inputs!D51 -> 300000 | E16: =Inputs!E21*Inputs!E51 -> 300000 | F16: =D16/Inputs!$D$4 -> 2309.6466
A17: Memo: purchased feed | B17: KES | C17: =C9 -> 60000 | D17: =D9 -> 50000 | E17: =E9 -> 40000 | F17: =D17/Inputs!$D$4 -> 384.9411
A18: Memo: drugs and vet inputs | B18: KES | C18: =C10 -> 45000 | D18: =D10 -> 40000 | E18: =E10 -> 35000 | F18: =D18/Inputs!$D$4 -> 307.95288

Sheet Goats
A1: Goats (annual, KES). All cells are live formulas from Inputs.
A2: Line | B2: Unit | C2: Low (adverse) | D2: Base | E2: High (favourable) | F2: Base in USD | G2: Note
A3: Production
A4: Kids sold (weaned less replacements) | B4: head | C4: =MAX(0,Inputs!C53*(Inputs!C54-Inputs!C55)) -> 7.84 | D4: =MAX(0,Inputs!D53*(Inputs!D54-Inputs!D55)) -> 9.6 | E4: =MAX(0,Inputs!E53*(Inputs!E54-Inputs!E55)) -> 11.36
A5: Sale price per head | B5: KES | C5: =Inputs!C56*Inputs!C57 -> 5500 | D5: =Inputs!D56*Inputs!D57 -> 6500 | E5: =Inputs!E56*Inputs!E57 -> 7830 | F5: =D5/Inputs!$D$4 -> 50.042344
A6: Revenue
A7: Sales revenue | B7: KES | C7: =C4*C5 -> 43120 | D7: =D4*D5 -> 62400 | E7: =E4*E5 -> 88948.8 | F7: =D7/Inputs!$D$4 -> 480.4065
A8: Variable costs
A9: Supplement/feed | B9: KES | C9: =Inputs!C22*Inputs!C58 -> 12000 | D9: =Inputs!D22*Inputs!D58 -> 10000 | E9: =Inputs!E22*Inputs!E58 -> 8000 | F9: =D9/Inputs!$D$4 -> 76.988221
A10: Drugs, deworm, vaccines | B10: KES | C10: =Inputs!C22*Inputs!C48 -> 9000 | D10: =Inputs!D22*Inputs!D48 -> 8000 | E10: =Inputs!E22*Inputs!E48 -> 7000 | F10: =D10/Inputs!$D$4 -> 61.590577
A11: Minerals | B11: KES | C11: =Inputs!C22*Inputs!C49 -> 2000 | D11: =Inputs!D22*Inputs!D49 -> 2000 | E11: =Inputs!E22*Inputs!E49 -> 2000 | F11: =D11/Inputs!$D$4 -> 15.397644
A12: Selling cost | B12: KES | C12: =C7*Inputs!C50 -> 2587.2 | D12: =D7*Inputs!D50 -> 2496 | E12: =E7*Inputs!E50 -> 2668.464 | F12: =D12/Inputs!$D$4 -> 19.21626
A13: Total variable costs | B13: KES | C13: =SUM(C9:C12) -> 25587.2 | D13: =SUM(D9:D12) -> 22496 | E13: =SUM(E9:E12) -> 19668.464 | F13: =D13/Inputs!$D$4 -> 173.1927
A14: Gross margin | B14: KES | C14: =C7-C13 -> 17532.8 | D14: =D7-D13 -> 39904 | E14: =E7-E13 -> 69280.336 | F14: =D14/Inputs!$D$4 -> 307.2138
A15: Gross margin per head | B15: KES/head | C15: =C14/Inputs!C22 -> 1753.28 | D15: =D14/Inputs!D22 -> 3990.4 | E15: =E14/Inputs!E22 -> 6928.0336
A16: Stock capital | B16: KES | C16: =Inputs!C22*Inputs!C59 -> 65000 | D16: =Inputs!D22*Inputs!D59 -> 65000 | E16: =Inputs!E22*Inputs!E59 -> 65000 | F16: =D16/Inputs!$D$4 -> 500.42344
A17: Memo: purchased feed | B17: KES | C17: =C9 -> 12000 | D17: =D9 -> 10000 | E17: =E9 -> 8000 | F17: =D17/Inputs!$D$4 -> 76.988221
A18: Memo: drugs and vet inputs | B18: KES | C18: =C10 -> 9000 | D18: =D10 -> 8000 | E18: =E10 -> 7000 | F18: =D18/Inputs!$D$4 -> 61.590577

Sheet Poultry
A1: Poultry (annual, KES). All cells are live formulas from Inputs.
A2: Line | B2: Unit | C2: Low (adverse) | D2: Base | E2: High (favourable) | F2: Base in USD | G2: Note
A3: Sasso
A4: Standing birds | B4: birds | C4: =Inputs!C69 -> 500 | D4: =Inputs!D69 -> 500 | E4: =Inputs!E69 -> 500
A5: Laying hens (hen slots) | B5: birds | C5: =Inputs!C69*Inputs!C70 -> 200 | D5: =Inputs!D69*Inputs!D70 -> 200 | E5: =Inputs!E69*Inputs!E70 -> 200
A6: Grower slots | B6: birds | C6: =Inputs!C69-C5 -> 300 | D6: =Inputs!D69-D5 -> 300 | E6: =Inputs!E69-E5 -> 300
A7: Saleable eggs | B7: eggs/yr | C7: =C5*Inputs!C71*(1-Inputs!C72) -> 21120 | D7: =D5*Inputs!D71*(1-Inputs!D72) -> 29100 | E7: =E5*Inputs!E71*(1-Inputs!E72) -> 35100
A8: Egg revenue | B8: KES | C8: =C7*Inputs!C73 -> 253440 | D8: =D7*Inputs!D73 -> 436500 | E8: =E7*Inputs!E73 -> 631800 | F8: =D8/Inputs!$D$4 -> 3360.5358
A9: Spent hens sold | B9: birds | C9: =C5*Inputs!C76 -> 160 | D9: =D5*Inputs!D76 -> 160 | E9: =E5*Inputs!E76 -> 160
A10: Spent hen revenue | B10: KES | C10: =C9*Inputs!C77 -> 48000 | D10: =D9*Inputs!D77 -> 64000 | E10: =E9*Inputs!E77 -> 80000 | F10: =D10/Inputs!$D$4 -> 492.72461
A11: Grower birds started per year | B11: birds | C11: =C6*Inputs!C82 -> 540 | D11: =D6*Inputs!D82 -> 600 | E11: =E6*Inputs!E82 -> 720
A12: Grower birds sold | B12: birds | C12: =C11*(1-Inputs!C83) -> 453.6 | D12: =D11*(1-Inputs!D83) -> 528 | E12: =E11*(1-Inputs!E83) -> 655.2
A13: Live-bird revenue | B13: KES | C13: =C12*Inputs!C86 -> 294840 | D13: =D12*Inputs!D86 -> 396000 | E13: =E12*Inputs!E86 -> 556920 | F13: =D13/Inputs!$D$4 -> 3048.7335
A14: Total revenue | B14: KES | C14: =C8+C10+C13 -> 596280 | D14: =D8+D10+D13 -> 896500 | E14: =E8+E10+E13 -> 1268720 | F14: =D14/Inputs!$D$4 -> 6901.994
A15: Replacement pullets needed (culls + deaths) | B15: birds | C15: =C5*(Inputs!C76+Inputs!C78) -> 178 | D15: =D5*(Inputs!D76+Inputs!D78) -> 174 | E15: =E5*(Inputs!E76+Inputs!E78) -> 172
A16: Replacement chicks bought (allowing rearing mortality) | B16: birds | C16: =C15/(1-Inputs!C79) -> 197.77778 | D16: =D15/(1-Inputs!D79) -> 189.13043 | E16: =E15/(1-Inputs!E79) -> 182.97872
A17: Chicks bought (replacements + growers) | B17: KES | C17: =(C16+C11)*Inputs!C87 -> 103288.89 | D17: =(D16+D11)*Inputs!D87 -> 94695.652 | E17: =(E16+E11)*Inputs!E87 -> 90297.872 | F17: =D17/Inputs!$D$4 -> 729.04498
A18: Feed: laying hens | B18: KES | C18: =C5*Inputs!C74/1000*365*(1-Inputs!C75)*Inputs!C61/70 -> 403585.71 | D18: =D5*Inputs!D74/1000*365*(1-Inputs!D75)*Inputs!D61/70 -> 290800.71 | E18: =E5*Inputs!E74/1000*365*(1-Inputs!E75)*Inputs!E61/70 -> 216810 | F18: =D18/Inputs!$D$4 -> 2238.823
A19: Feed: replacement pullets | B19: KES | C19: =C16*Inputs!C80*(1-Inputs!C85)*Inputs!C62/70 -> 97900 | D19: =D16*Inputs!D80*(1-Inputs!D85)*Inputs!D62/70 -> 68086.957 | E19: =E16*Inputs!E80*(1-Inputs!E85)*Inputs!E62/70 -> 45875.38 | F19: =D19/Inputs!$D$4 -> 524.18936
A20: Feed: growers | B20: KES | C20: =C11*Inputs!C84*(1-Inputs!C85)*Inputs!C62/70 -> 291600 | D20: =D11*Inputs!D84*(1-Inputs!D85)*Inputs!D62/70 -> 237600 | E20: =E11*Inputs!E84*(1-Inputs!E85)*Inputs!E62/70 -> 200571.43 | F20: =D20/Inputs!$D$4 -> 1829.2401
A21: Drugs and vaccines | B21: KES | C21: =C5*Inputs!C81+(C16+C11)*Inputs!C88 -> 68266.667 | D21: =D5*Inputs!D81+(D16+D11)*Inputs!D88 -> 51565.217 | E21: =E5*Inputs!E81+(E16+E11)*Inputs!E88 -> 43089.362 | F21: =D21/Inputs!$D$4 -> 396.99143
A22: Brooding fuel and bedding | B22: KES | C22: =(C16+C11)*Inputs!C66 -> 14755.556 | D22: =(D16+D11)*Inputs!D66 -> 11836.957 | E22: =(E16+E11)*Inputs!E66 -> 10835.745 | F22: =D22/Inputs!$D$4 -> 91.130622
A23: Egg packaging | B23: KES | C23: =C7/30*Inputs!C64 -> 17600 | D23: =D7/30*Inputs!D64 -> 24250 | E23: =E7/30*Inputs!E64 -> 29250 | F23: =D23/Inputs!$D$4 -> 186.69644
A24: Selling costs | B24: KES | C24: =C8*Inputs!C63+(C10+C13)*Inputs!C65 -> 27279.6 | D24: =D8*Inputs!D63+(D10+D13)*Inputs!D65 -> 31495 | E24: =E8*Inputs!E63+(E10+E13)*Inputs!E65 -> 31743.6 | F24: =D24/Inputs!$D$4 -> 242.4744
A25: Total variable costs | B25: KES | C25: =C17+C18+C19+C20+C21+C22+C23+C24 -> 1024276.4 | D25: =D17+D18+D19+D20+D21+D22+D23+D24 -> 810330.5 | E25: =E17+E18+E19+E20+E21+E22+E23+E24 -> 668473.39 | F25: =D25/Inputs!$D$4 -> 6238.5903
A26: Gross margin | B26: KES | C26: =C14-C25 -> -427996.43 | D26: =D14-D25 -> 86169.503 | E26: =E14-E25 -> 600246.61 | F26: =D26/Inputs!$D$4 -> 663.40367
A27: Gross margin per standing bird | B27: KES/bird | C27: =C26/C4 -> -855.99285 | D27: =D26/D4 -> 172.33901 | E27: =E26/E4 -> 1200.4932
A28: Unit margin per hen slot (per year) | B28: KES/bird | C28: =Inputs!C71*(1-Inputs!C72)*(Inputs!C73*(1-Inputs!C63)-Inputs!C64/30)+Inputs!C76*Inputs!C77*(1-Inputs!C65)-(Inputs!C76+Inputs!C78)/(1-Inputs!C79)*(Inputs!C87+Inputs!C66+Inputs!C88+Inputs!C80*(1-Inputs!C85)*Inputs!C62/70)-Inputs!C74/1000*365*(1-Inputs!C75)*Inputs!C61/70-Inputs!C81 -> -1488.4721 | D28: =Inputs!D71*(1-Inputs!D72)*(Inputs!D73*(1-Inputs!D63)-Inputs!D64/30)+Inputs!D76*Inputs!D77*(1-Inputs!D65)-(Inputs!D76+Inputs!D78)/(1-Inputs!D79)*(Inputs!D87+Inputs!D66+Inputs!D88+Inputs!D80*(1-Inputs!D85)*Inputs!D62/70)-Inputs!D74/1000*365*(1-Inputs!D75)*Inputs!D61/70-Inputs!D81 -> 243.04752 | E28: =Inputs!E71*(1-Inputs!E72)*(Inputs!E73*(1-Inputs!E63)-Inputs!E64/30)+Inputs!E76*Inputs!E77*(1-Inputs!E65)-(Inputs!E76+Inputs!E78)/(1-Inputs!E79)*(Inputs!E87+Inputs!E66+Inputs!E88+Inputs!E80*(1-Inputs!E85)*Inputs!E62/70)-Inputs!E74/1000*365*(1-Inputs!E75)*Inputs!E61/70-Inputs!E81 -> 1814.2282
A29: Unit margin per grower slot (per year) | B29: KES/bird | C29: =Inputs!C82*((1-Inputs!C83)*Inputs!C86*(1-Inputs!C65)-Inputs!C87-Inputs!C66-Inputs!C88-Inputs!C84*(1-Inputs!C85)*Inputs!C62/70) -> -434.34 | D29: =Inputs!D82*((1-Inputs!D83)*Inputs!D86*(1-Inputs!D65)-Inputs!D87-Inputs!D66-Inputs!D88-Inputs!D84*(1-Inputs!D85)*Inputs!D62/70) -> 125.2 | E29: =Inputs!E82*((1-Inputs!E83)*Inputs!E86*(1-Inputs!E65)-Inputs!E87-Inputs!E66-Inputs!E88-Inputs!E84*(1-Inputs!E85)*Inputs!E62/70) -> 791.33657
A30: Check: slot margins reproduce gross margin (should be 0) | B30: KES | C30: =C26-(C5*C28+C6*C29) -> 0 | D30: =D26-(D5*D28+D6*D29) -> 0 | E30: =E26-(E5*E28+E6*E29) -> 0 | F30: =D30/Inputs!$D$4 -> 0
A31: Stock capital | B31: KES | C31: =Inputs!C69*Inputs!C89 -> 250000 | D31: =Inputs!D69*Inputs!D89 -> 250000 | E31: =Inputs!E69*Inputs!E89 -> 250000 | F31: =D31/Inputs!$D$4 -> 1924.7055
A32: Memo: purchased feed | B32: KES | C32: =C18+C19+C20 -> 793085.71 | D32: =D18+D19+D20 -> 596487.67 | E32: =E18+E19+E20 -> 463256.81 | F32: =D32/Inputs!$D$4 -> 4592.2525
A33: Kuroiler
A34: Standing birds | B34: birds | C34: =Inputs!C91 -> 500 | D34: =Inputs!D91 -> 500 | E34: =Inputs!E91 -> 500
A35: Laying hens (hen slots) | B35: birds | C35: =Inputs!C91*Inputs!C92 -> 200 | D35: =Inputs!D91*Inputs!D92 -> 200 | E35: =Inputs!E91*Inputs!E92 -> 200
A36: Grower slots | B36: birds | C36: =Inputs!C91-C35 -> 300 | D36: =Inputs!D91-D35 -> 300 | E36: =Inputs!E91-E35 -> 300
A37: Saleable eggs | B37: eggs/yr | C37: =C35*Inputs!C93*(1-Inputs!C94) -> 21120 | D37: =D35*Inputs!D93*(1-Inputs!D94) -> 29100 | E37: =E35*Inputs!E93*(1-Inputs!E94) -> 35100
A38: Egg revenue | B38: KES | C38: =C37*Inputs!C95 -> 253440 | D38: =D37*Inputs!D95 -> 436500 | E38: =E37*Inputs!E95 -> 631800 | F38: =D38/Inputs!$D$4 -> 3360.5358
A39: Spent hens sold | B39: birds | C39: =C35*Inputs!C98 -> 160 | D39: =D35*Inputs!D98 -> 160 | E39: =E35*Inputs!E98 -> 160
A40: Spent hen revenue | B40: KES | C40: =C39*Inputs!C99 -> 48000 | D40: =D39*Inputs!D99 -> 64000 | E40: =E39*Inputs!E99 -> 80000 | F40: =D40/Inputs!$D$4 -> 492.72461
...

Sheet Mix
A1: Mix (annual, KES). All cells are live formulas from Inputs.
A2: Line | B2: Unit | C2: Low (adverse) | D2: Base | E2: High (favourable) | F2: Base in USD | G2: Note
A3: Hen share applied to all four chicken breeds (others unchanged). Other columns hold B12 option 2 value at that mix
A4: Hen share 0% of chicken flock
A5: Chicken gross margin at 0% hens | B5: KES | C5: =Inputs!C69*(0*Poultry!C28+1*Poultry!C29)+Inputs!C91*(0*Poultry!C58+1*Poultry!C59)+Inputs!C113*(0*Poultry!C88+1*Poultry!C89)+Inputs!C135*(0*Poultry!C118+1*Poultry!C119) -> -868680 | D5: =Inputs!D69*(0*Poultry!D28+1*Poultry!D29)+Inputs!D91*(0*Poultry!D58+1*Poultry!D59)+Inputs!D113*(0*Poultry!D88+1*Poultry!D89)+Inputs!D135*(0*Poultry!D118+1*Poultry!D119) -> 250400 | E5: =Inputs!E69*(0*Poultry!E28+1*Poultry!E29)+Inputs!E91*(0*Poultry!E58+1*Poultry!E59)+Inputs!E113*(0*Poultry!E88+1*Poultry!E89)+Inputs!E135*(0*Poultry!E118+1*Poultry!E119) -> 1582673.1 | F5: =D5/Inputs!$D$4 -> 1927.785
A6: Egg trays to sell per day (chickens only) | B6: trays/day | C6: =(Inputs!C69*0*Inputs!C71*(1-Inputs!C72)+Inputs!C91*0*Inputs!C93*(1-Inputs!C94)+Inputs!C113*0*Inputs!C115*(1-Inputs!C116)+Inputs!C135*0*Inputs!C137*(1-Inputs!C138))/30/365 -> 0 | D6: =(Inputs!D69*0*Inputs!D71*(1-Inputs!D72)+Inputs!D91*0*Inputs!D93*(1-Inputs!D94)+Inputs!D113*0*Inputs!D115*(1-Inputs!D116)+Inputs!D135*0*Inputs!D137*(1-Inputs!D138))/30/365 -> 0 | E6: =(Inputs!E69*0*Inputs!E71*(1-Inputs!E72)+Inputs!E91*0*Inputs!E93*(1-Inputs!E94)+Inputs!E113*0*Inputs!E115*(1-Inputs!E116)+Inputs!E135*0*Inputs!E137*(1-Inputs!E138))/30/365 -> 0
A7: Grower birds to sell per week (chickens only) | B7: birds/wk | C7: =(Inputs!C69*1*Inputs!C82*(1-Inputs!C83)+Inputs!C91*1*Inputs!C104*(1-Inputs!C105)+Inputs!C113*1*Inputs!C126*(1-Inputs!C127)+Inputs!C135*1*Inputs!C148*(1-Inputs!C149))/52 -> 58.153846 | D7: =(Inputs!D69*1*Inputs!D82*(1-Inputs!D83)+Inputs!D91*1*Inputs!D104*(1-Inputs!D105)+Inputs!D113*1*Inputs!D126*(1-Inputs!D127)+Inputs!D135*1*Inputs!D148*(1-Inputs!D149))/52 -> 67.692308 | E7: =(Inputs!E69*1*Inputs!E82*(1-Inputs!E83)+Inputs!E91*1*Inputs!E104*(1-Inputs!E105)+Inputs!E113*1*Inputs!E126*(1-Inputs!E127)+Inputs!E135*1*Inputs!E148*(1-Inputs!E149))/52 -> 84
A8: Farm OMBM at this mix | B8: KES | C8: =Farm_PnL!C46-Poultry!C256+C5 -> -3838062.9 | D8: =Farm_PnL!D46-Poultry!D256+D5 -> -1627086.5 | E8: =Farm_PnL!E46-Poultry!E256+E5 -> 771798.8 | F8: =D8/Inputs!$D$4 -> -12526.65
A9: B12 owner-operator value at this mix | B9: KES | C9: =B12!C21-Poultry!C256+C5 -> -5309046.4 | D9: =B12!D21-Poultry!D256+D5 -> -2472467 | E9: =B12!E21-Poultry!E256+E5 -> 378040.52 | F9: =D9/Inputs!$D$4 -> -19035.083
A10: Hen share 20% of chicken flock
A11: Chicken gross margin at 20% hens | B11: KES | C11: =Inputs!C69*(0.2*Poultry!C28+0.8*Poultry!C29)+Inputs!C91*(0.2*Poultry!C58+0.8*Poultry!C59)+Inputs!C113*(0.2*Poultry!C88+0.8*Poultry!C89)+Inputs!C135*(0.2*Poultry!C118+0.8*Poultry!C119) -> -1290332.9 | D11: =Inputs!D69*(0.2*Poultry!D28+0.8*Poultry!D29)+Inputs!D91*(0.2*Poultry!D58+0.8*Poultry!D59)+Inputs!D113*(0.2*Poultry!D88+0.8*Poultry!D89)+Inputs!D135*(0.2*Poultry!D118+0.8*Poultry!D119) -> 297539.01 | E11: =Inputs!E69*(0.2*Poultry!E28+0.8*Poultry!E29)+Inputs!E91*(0.2*Poultry!E58+0.8*Poultry!E59)+Inputs!E113*(0.2*Poultry!E88+0.8*Poultry!E89)+Inputs!E135*(0.2*Poultry!E118+0.8*Poultry!E119) -> 1991829.8 | F11: =D11/Inputs!$D$4 -> 2290.6999
A12: Egg trays to sell per day (chickens only) | B12: trays/day | C12: =(Inputs!C69*0.2*Inputs!C71*(1-Inputs!C72)+Inputs!C91*0.2*Inputs!C93*(1-Inputs!C94)+Inputs!C113*0.2*Inputs!C115*(1-Inputs!C116)+Inputs!C135*0.2*Inputs!C137*(1-Inputs!C138))/30/365 -> 3.8575342 | D12: =(Inputs!D69*0.2*Inputs!D71*(1-Inputs!D72)+Inputs!D91*0.2*Inputs!D93*(1-Inputs!D94)+Inputs!D113*0.2*Inputs!D115*(1-Inputs!D116)+Inputs!D135*0.2*Inputs!D137*(1-Inputs!D138))/30/365 -> 5.3150685 | E12: =(Inputs!E69*0.2*Inputs!E71*(1-Inputs!E72)+Inputs!E91*0.2*Inputs!E93*(1-Inputs!E94)+Inputs!E113*0.2*Inputs!E115*(1-Inputs!E116)+Inputs!E135*0.2*Inputs!E137*(1-Inputs!E138))/30/365 -> 6.4109589
A13: Grower birds to sell per week (chickens only) | B13: birds/wk | C13: =(Inputs!C69*0.8*Inputs!C82*(1-Inputs!C83)+Inputs!C91*0.8*Inputs!C104*(1-Inputs!C105)+Inputs!C113*0.8*Inputs!C126*(1-Inputs!C127)+Inputs!C135*0.8*Inputs!C148*(1-Inputs!C149))/52 -> 46.523077 | D13: =(Inputs!D69*0.8*Inputs!D82*(1-Inputs!D83)+Inputs!D91*0.8*Inputs!D104*(1-Inputs!D105)+Inputs!D113*0.8*Inputs!D126*(1-Inputs!D127)+Inputs!D135*0.8*Inputs!D148*(1-Inputs!D149))/52 -> 54.153846 | E13: =(Inputs!E69*0.8*Inputs!E82*(1-Inputs!E83)+Inputs!E91*0.8*Inputs!E104*(1-Inputs!E105)+Inputs!E113*0.8*Inputs!E126*(1-Inputs!E127)+Inputs!E135*0.8*Inputs!E148*(1-Inputs!E149))/52 -> 67.2
A14: Farm OMBM at this mix | B14: KES | C14: =Farm_PnL!C46-Poultry!C256+C11 -> -4259715.7 | D14: =Farm_PnL!D46-Poultry!D256+D11 -> -1579947.5 | E14: =Farm_PnL!E46-Poultry!E256+E11 -> 1180955.5 | F14: =D14/Inputs!$D$4 -> -12163.735
A15: B12 owner-operator value at this mix | B15: KES | C15: =B12!C21-Poultry!C256+C11 -> -5730699.2 | D15: =B12!D21-Poultry!D256+D11 -> -2425328 | E15: =B12!E21-Poultry!E256+E11 -> 787197.18 | F15: =D15/Inputs!$D$4 -> -18672.169
A16: Hen share 40% of chicken flock
A17: Chicken gross margin at 40% hens | B17: KES | C17: =Inputs!C69*(0.4*Poultry!C28+0.6*Poultry!C29)+Inputs!C91*(0.4*Poultry!C58+0.6*Poultry!C59)+Inputs!C113*(0.4*Poultry!C88+0.6*Poultry!C89)+Inputs!C135*(0.4*Poultry!C118+0.6*Poultry!C119) -> -1711985.7 | D17: =Inputs!D69*(0.4*Poultry!D28+0.6*Poultry!D29)+Inputs!D91*(0.4*Poultry!D58+0.6*Poultry!D59)+Inputs!D113*(0.4*Poultry!D88+0.6*Poultry!D89)+Inputs!D135*(0.4*Poultry!D118+0.6*Poultry!D119) -> 344678.01 | E17: =Inputs!E69*(0.4*Poultry!E28+0.6*Poultry!E29)+Inputs!E91*(0.4*Poultry!E58+0.6*Poultry!E59)+Inputs!E113*(0.4*Poultry!E88+0.6*Poultry!E89)+Inputs!E135*(0.4*Poultry!E118+0.6*Poultry!E119) -> 2400986.5 | F17: =D17/Inputs!$D$4 -> 2653.6147
A18: Egg trays to sell per day (chickens only) | B18: trays/day | C18: =(Inputs!C69*0.4*Inputs!C71*(1-Inputs!C72)+Inputs!C91*0.4*Inputs!C93*(1-Inputs!C94)+Inputs!C113*0.4*Inputs!C115*(1-Inputs!C116)+Inputs!C135*0.4*Inputs!C137*(1-Inputs!C138))/30/365 -> 7.7150685 | D18: =(Inputs!D69*0.4*Inputs!D71*(1-Inputs!D72)+Inputs!D91*0.4*Inputs!D93*(1-Inputs!D94)+Inputs!D113*0.4*Inputs!D115*(1-Inputs!D116)+Inputs!D135*0.4*Inputs!D137*(1-Inputs!D138))/30/365 -> 10.630137 | E18: =(Inputs!E69*0.4*Inputs!E71*(1-Inputs!E72)+Inputs!E91*0.4*Inputs!E93*(1-Inputs!E94)+Inputs!E113*0.4*Inputs!E115*(1-Inputs!E116)+Inputs!E135*0.4*Inputs!E137*(1-Inputs!E138))/30/365 -> 12.821918
A19: Grower birds to sell per week (chickens only) | B19: birds/wk | C19: =(Inputs!C69*0.6*Inputs!C82*(1-Inputs!C83)+Inputs!C91*0.6*Inputs!C104*(1-Inputs!C105)+Inputs!C113*0.6*Inputs!C126*(1-Inputs!C127)+Inputs!C135*0.6*Inputs!C148*(1-Inputs!C149))/52 -> 34.892308 | D19: =(Inputs!D69*0.6*Inputs!D82*(1-Inputs!D83)+Inputs!D91*0.6*Inputs!D104*(1-Inputs!D105)+Inputs!D113*0.6*Inputs!D126*(1-Inputs!D127)+Inputs!D135*0.6*Inputs!D148*(1-Inputs!D149))/52 -> 40.615385 | E19: =(Inputs!E69*0.6*Inputs!E82*(1-Inputs!E83)+Inputs!E91*0.6*Inputs!E104*(1-Inputs!E105)+Inputs!E113*0.6*Inputs!E126*(1-Inputs!E127)+Inputs!E135*0.6*Inputs!E148*(1-Inputs!E149))/52 -> 50.4
A20: Farm OMBM at this mix | B20: KES | C20: =Farm_PnL!C46-Poultry!C256+C17 -> -4681368.6 | D20: =Farm_PnL!D46-Poultry!D256+D17 -> -1532808.5 | E20: =Farm_PnL!E46-Poultry!E256+E17 -> 1590112.1 | F20: =D20/Inputs!$D$4 -> -11800.82
A21: B12 owner-operator value at this mix | B21: KES | C21: =B12!C21-Poultry!C256+C17 -> -6152352.1 | D21: =B12!D21-Poultry!D256+D17 -> -2378189 | E21: =B12!E21-Poultry!E256+E17 -> 1196353.8 | F21: =D21/Inputs!$D$4 -> -18309.254
A22: Hen share 60% of chicken flock
A23: Chicken gross margin at 60% hens | B23: KES | C23: =Inputs!C69*(0.6*Poultry!C28+0.4*Poultry!C29)+Inputs!C91*(0.6*Poultry!C58+0.4*Poultry!C59)+Inputs!C113*(0.6*Poultry!C88+0.4*Poultry!C89)+Inputs!C135*(0.6*Poultry!C118+0.4*Poultry!C119) -> -2133638.6 | D23: =Inputs!D69*(0.6*Poultry!D28+0.4*Poultry!D29)+Inputs!D91*(0.6*Poultry!D58+0.4*Poultry!D59)+Inputs!D113*(0.6*Poultry!D88+0.4*Poultry!D89)+Inputs!D135*(0.6*Poultry!D118+0.4*Poultry!D119) -> 391817.02 | E23: =Inputs!E69*(0.6*Poultry!E28+0.4*Poultry!E29)+Inputs!E91*(0.6*Poultry!E58+0.4*Poultry!E59)+Inputs!E113*(0.6*Poultry!E88+0.4*Poultry!E89)+Inputs!E135*(0.6*Poultry!E118+0.4*Poultry!E119) -> 2810143.1 | F23: =D23/Inputs!$D$4 -> 3016.5295
A24: Egg trays to sell per day (chickens only) | B24: trays/day | C24: =(Inputs!C69*0.6*Inputs!C71*(1-Inputs!C72)+Inputs!C91*0.6*Inputs!C93*(1-Inputs!C94)+Inputs!C113*0.6*Inputs!C115*(1-Inputs!C116)+Inputs!C135*0.6*Inputs!C137*(1-Inputs!C138))/30/365 -> 11.572603 | D24: =(Inputs!D69*0.6*Inputs!D71*(1-Inputs!D72)+Inputs!D91*0.6*Inputs!D93*(1-Inputs!D94)+Inputs!D113*0.6*Inputs!D115*(1-Inputs!D116)+Inputs!D135*0.6*Inputs!D137*(1-Inputs!D138))/30/365 -> 15.945205 | E24: =(Inputs!E69*0.6*Inputs!E71*(1-Inputs!E72)+Inputs!E91*0.6*Inputs!E93*(1-Inputs!E94)+Inputs!E113*0.6*Inputs!E115*(1-Inputs!E116)+Inputs!E135*0.6*Inputs!E137*(1-Inputs!E138))/30/365 -> 19.232877
A25: Grower birds to sell per week (chickens only) | B25: birds/wk | C25: =(Inputs!C69*0.4*Inputs!C82*(1-Inputs!C83)+Inputs!C91*0.4*Inputs!C104*(1-Inputs!C105)+Inputs!C113*0.4*Inputs!C126*(1-Inputs!C127)+Inputs!C135*0.4*Inputs!C148*(1-Inputs!C149))/52 -> 23.261538 | D25: =(Inputs!D69*0.4*Inputs!D82*(1-Inputs!D83)+Inputs!D91*0.4*Inputs!D104*(1-Inputs!D105)+Inputs!D113*0.4*Inputs!D126*(1-Inputs!D127)+Inputs!D135*0.4*Inputs!D148*(1-Inputs!D149))/52 -> 27.076923 | E25: =(Inputs!E69*0.4*Inputs!E82*(1-Inputs!E83)+Inputs!E91*0.4*Inputs!E104*(1-Inputs!E105)+Inputs!E113*0.4*Inputs!E126*(1-Inputs!E127)+Inputs!E135*0.4*Inputs!E148*(1-Inputs!E149))/52 -> 33.6
A26: Farm OMBM at this mix | B26: KES | C26: =Farm_PnL!C46-Poultry!C256+C23 -> -5103021.4 | D26: =Farm_PnL!D46-Poultry!D256+D23 -> -1485669.5 | E26: =Farm_PnL!E46-Poultry!E256+E23 -> 1999268.8 | F26: =D26/Inputs!$D$4 -> -11437.905
A27: B12 owner-operator value at this mix | B27: KES | C27: =B12!C21-Poultry!C256+C23 -> -6574004.9 | D27: =B12!D21-Poultry!D256+D23 -> -2331050 | E27: =B12!E21-Poultry!E256+E23 -> 1605510.5 | F27: =D27/Inputs!$D$4 -> -17946.339
A28: Hen share 80% of chicken flock
A29: Chicken gross margin at 80% hens | B29: KES | C29: =Inputs!C69*(0.8*Poultry!C28+0.2*Poultry!C29)+Inputs!C91*(0.8*Poultry!C58+0.2*Poultry!C59)+Inputs!C113*(0.8*Poultry!C88+0.2*Poultry!C89)+Inputs!C135*(0.8*Poultry!C118+0.2*Poultry!C119) -> -2555291.4 | D29: =Inputs!D69*(0.8*Poultry!D28+0.2*Poultry!D29)+Inputs!D91*(0.8*Poultry!D58+0.2*Poultry!D59)+Inputs!D113*(0.8*Poultry!D88+0.2*Poultry!D89)+Inputs!D135*(0.8*Poultry!D118+0.2*Poultry!D119) -> 438956.02 | E29: =Inputs!E69*(0.8*Poultry!E28+0.2*Poultry!E29)+Inputs!E91*(0.8*Poultry!E58+0.2*Poultry!E59)+Inputs!E113*(0.8*Poultry!E88+0.2*Poultry!E89)+Inputs!E135*(0.8*Poultry!E118+0.2*Poultry!E119) -> 3219299.8 | F29: =D29/Inputs!$D$4 -> 3379.4443
A30: Egg trays to sell per day (chickens only) | B30: trays/day | C30: =(Inputs!C69*0.8*Inputs!C71*(1-Inputs!C72)+Inputs!C91*0.8*Inputs!C93*(1-Inputs!C94)+Inputs!C113*0.8*Inputs!C115*(1-Inputs!C116)+Inputs!C135*0.8*Inputs!C137*(1-Inputs!C138))/30/365 -> 15.430137 | D30: =(Inputs!D69*0.8*Inputs!D71*(1-Inputs!D72)+Inputs!D91*0.8*Inputs!D93*(1-Inputs!D94)+Inputs!D113*0.8*Inputs!D115*(1-Inputs!D116)+Inputs!D135*0.8*Inputs!D137*(1-Inputs!D138))/30/365 -> 21.260274 | E30: =(Inputs!E69*0.8*Inputs!E71*(1-Inputs!E72)+Inputs!E91*0.8*Inputs!E93*(1-Inputs!E94)+Inputs!E113*0.8*Inputs!E115*(1-Inputs!E116)+Inputs!E135*0.8*Inputs!E137*(1-Inputs!E138))/30/365 -> 25.643836
A31: Grower birds to sell per week (chickens only) | B31: birds/wk | C31: =(Inputs!C69*0.2*Inputs!C82*(1-Inputs!C83)+Inputs!C91*0.2*Inputs!C104*(1-Inputs!C105)+Inputs!C113*0.2*Inputs!C126*(1-Inputs!C127)+Inputs!C135*0.2*Inputs!C148*(1-Inputs!C149))/52 -> 11.630769 | D31: =(Inputs!D69*0.2*Inputs!D82*(1-Inputs!D83)+Inputs!D91*0.2*Inputs!D104*(1-Inputs!D105)+Inputs!D113*0.2*Inputs!D126*(1-Inputs!D127)+Inputs!D135*0.2*Inputs!D148*(1-Inputs!D149))/52 -> 13.538462 | E31: =(Inputs!E69*0.2*Inputs!E82*(1-Inputs!E83)+Inputs!E91*0.2*Inputs!E104*(1-Inputs!E105)+Inputs!E113*0.2*Inputs!E126*(1-Inputs!E127)+Inputs!E135*0.2*Inputs!E148*(1-Inputs!E149))/52 -> 16.8
A32: Farm OMBM at this mix | B32: KES | C32: =Farm_PnL!C46-Poultry!C256+C29 -> -5524674.3 | D32: =Farm_PnL!D46-Poultry!D256+D29 -> -1438530.5 | E32: =Farm_PnL!E46-Poultry!E256+E29 -> 2408425.4 | F32: =D32/Inputs!$D$4 -> -11074.99
A33: B12 owner-operator value at this mix | B33: KES | C33: =B12!C21-Poultry!C256+C29 -> -6995657.8 | D33: =B12!D21-Poultry!D256+D29 -> -2283911 | E33: =B12!E21-Poultry!E256+E29 -> 2014667.1 | F33: =D33/Inputs!$D$4 -> -17583.424
A34: Hen share 100% of chicken flock
A35: Chicken gross margin at 100% hens | B35: KES | C35: =Inputs!C69*(1*Poultry!C28+0*Poultry!C29)+Inputs!C91*(1*Poultry!C58+0*Poultry!C59)+Inputs!C113*(1*Poultry!C88+0*Poultry!C89)+Inputs!C135*(1*Poultry!C118+0*Poultry!C119) -> -2976944.3 | D35: =Inputs!D69*(1*Poultry!D28+0*Poultry!D29)+Inputs!D91*(1*Poultry!D58+0*Poultry!D59)+Inputs!D113*(1*Poultry!D88+0*Poultry!D89)+Inputs!D135*(1*Poultry!D118+0*Poultry!D119) -> 486095.03 | E35: =Inputs!E69*(1*Poultry!E28+0*Poultry!E29)+Inputs!E91*(1*Poultry!E58+0*Poultry!E59)+Inputs!E113*(1*Poultry!E88+0*Poultry!E89)+Inputs!E135*(1*Poultry!E118+0*Poultry!E119) -> 3628456.4 | F35: =D35/Inputs!$D$4 -> 3742.3592
A36: Egg trays to sell per day (chickens only) | B36: trays/day | C36: =(Inputs!C69*1*Inputs!C71*(1-Inputs!C72)+Inputs!C91*1*Inputs!C93*(1-Inputs!C94)+Inputs!C113*1*Inputs!C115*(1-Inputs!C116)+Inputs!C135*1*Inputs!C137*(1-Inputs!C138))/30/365 -> 19.287671 | D36: =(Inputs!D69*1*Inputs!D71*(1-Inputs!D72)+Inputs!D91*1*Inputs!D93*(1-Inputs!D94)+Inputs!D113*1*Inputs!D115*(1-Inputs!D116)+Inputs!D135*1*Inputs!D137*(1-Inputs!D138))/30/365 -> 26.575342 | E36: =(Inputs!E69*1*Inputs!E71*(1-Inputs!E72)+Inputs!E91*1*Inputs!E93*(1-Inputs!E94)+Inputs!E113*1*Inputs!E115*(1-Inputs!E116)+Inputs!E135*1*Inputs!E137*(1-Inputs!E138))/30/365 -> 32.054795
A37: Grower birds to sell per week (chickens only) | B37: birds/wk | C37: =(Inputs!C69*0*Inputs!C82*(1-Inputs!C83)+Inputs!C91*0*Inputs!C104*(1-Inputs!C105)+Inputs!C113*0*Inputs!C126*(1-Inputs!C127)+Inputs!C135*0*Inputs!C148*(1-Inputs!C149))/52 -> 0 | D37: =(Inputs!D69*0*Inputs!D82*(1-Inputs!D83)+Inputs!D91*0*Inputs!D104*(1-Inputs!D105)+Inputs!D113*0*Inputs!D126*(1-Inputs!D127)+Inputs!D135*0*Inputs!D148*(1-Inputs!D149))/52 -> 0 | E37: =(Inputs!E69*0*Inputs!E82*(1-Inputs!E83)+Inputs!E91*0*Inputs!E104*(1-Inputs!E105)+Inputs!E113*0*Inputs!E126*(1-Inputs!E127)+Inputs!E135*0*Inputs!E148*(1-Inputs!E149))/52 -> 0
A38: Farm OMBM at this mix | B38: KES | C38: =Farm_PnL!C46-Poultry!C256+C35 -> -5946327.1 | D38: =Farm_PnL!D46-Poultry!D256+D35 -> -1391391.5 | E38: =Farm_PnL!E46-Poultry!E256+E35 -> 2817582.1 | F38: =D38/Inputs!$D$4 -> -10712.076
A39: B12 owner-operator value at this mix | B39: KES | C39: =B12!C21-Poultry!C256+C35 -> -7417310.6 | D39: =B12!D21-Poultry!D256+D35 -> -2236772 | E39: =B12!E21-Poultry!E256+E35 -> 2423823.8 | F39: =D39/Inputs!$D$4 -> -17220.509

Sheet Labour
A1: Labour (annual, KES). All cells are live formulas from Inputs.
A2: Line | B2: Unit | C2: Low (adverse) | D2: Base | E2: High (favourable) | F2: Base in USD | G2: Note
A3: Pay (owner-reported KES 22,000 each; one is a relative)
A4: Staff 1 | B4: KES/month | C4: =Inputs!C248 -> 22000 | D4: =Inputs!D248 -> 22000 | E4: =Inputs!E248 -> 22000
A5: Staff 2 (relative; placeholder) | B5: KES/month | C5: =Inputs!C249 -> 22000 | D5: =Inputs!D249 -> 22000 | E5: =Inputs!E249 -> 22000
A6: Staff 3 | B6: KES/month | C6: =Inputs!C250 -> 22000 | D6: =Inputs!D250 -> 22000 | E6: =Inputs!E250 -> 22000
A7: Pay as multiple of legal stockman minimum (each) | B7: x | C7: =Inputs!C248/Inputs!C246 -> 2.3820403 | D7: =Inputs!D248/Inputs!D246 -> 2.3820403 | E7: =Inputs!E248/Inputs!E246 -> 2.3820403 | G7: Foreman/clerk minimum is higher: see next row
A8: Pay as multiple of legal foreman/clerk minimum | B8: x | C8: =Inputs!C248/Inputs!C247 -> 1.5249048 | D8: =Inputs!D248/Inputs!D247 -> 1.5249048 | E8: =Inputs!E248/Inputs!E247 -> 1.5249048
A9: Annual cost
A10: Basic pay (x12) | B10: KES | C10: =(C4+C5+C6)*12 -> 792000 | D10: =(D4+D5+D6)*12 -> 792000 | E10: =(E4+E5+E6)*12 -> 792000 | F10: =D10/Inputs!$D$4 -> 6097.4671
A11: Employer NSSF + housing levy + NITA | B11: KES | C11: =(C4+C5+C6)*12*(Inputs!C251+Inputs!C252)+3*12*Inputs!C253 -> 61200 | D11: =(D4+D5+D6)*12*(Inputs!D251+Inputs!D252)+3*12*Inputs!D253 -> 61200 | E11: =(E4+E5+E6)*12*(Inputs!E251+Inputs!E252)+3*12*Inputs!E253 -> 61200 | F11: =D11/Inputs!$D$4 -> 471.16791
A12: Casual relief labour (leave, peaks) | B12: KES | C12: =Inputs!C254*Inputs!C255 -> 17500 | D12: =Inputs!D254*Inputs!D255 -> 15000 | E12: =Inputs!E254*Inputs!E255 -> 12500 | F12: =D12/Inputs!$D$4 -> 115.48233
A13: Task hours required per year | B13: h | C13: =(Inputs!C258+Inputs!C259+Inputs!C260+Inputs!C262+Poultry!C244/100*Inputs!C261)*365 -> 7135.75 | D13: =(Inputs!D258+Inputs!D259+Inputs!D260+Inputs!D262+Poultry!D244/100*Inputs!D261)*365 -> 5869.2 | E13: =(Inputs!E258+Inputs!E259+Inputs!E260+Inputs!E262+Poultry!E244/100*Inputs!E261)*365 -> 5015.465
A14: Productive hours per person per year | B14: h | C14: =Inputs!C256*Inputs!C257 -> 2160 | D14: =Inputs!D256*Inputs!D257 -> 2160 | E14: =Inputs!E256*Inputs!E257 -> 2160
A15: FTE required | B15: FTE | C15: =C13/C14 -> 3.303588 | D15: =D13/D14 -> 2.7172222 | E15: =E13/E14 -> 2.3219745
A16: Utilisation of 3 staff | B16: % | C16: =C15/3 -> 1.101196 | D16: =D15/3 -> 0.90574074 | E16: =E15/3 -> 0.77399151
A17: Hours beyond the 3 staff (to be covered by extra casuals) | B17: h | C17: =MAX(0,C13-3*C14) -> 655.75 | D17: =MAX(0,D13-3*D14) -> 0 | E17: =MAX(0,E13-3*E14) -> 0
A18: Extra casual labour for hours beyond 3 staff | B18: KES | C18: =C17/8*Inputs!C255 -> 40984.375 | D18: =D17/8*Inputs!D255 -> 0 | E18: =E17/8*Inputs!E255 -> 0 | F18: =D18/Inputs!$D$4 -> 0
A19: Total hired labour cost | B19: KES | C19: =C10+C11+C12+C18 -> 911684.38 | D19: =D10+D11+D12+D18 -> 868200 | E19: =E10+E11+E12+E18 -> 865700 | F19: =D19/Inputs!$D$4 -> 6684.1173
A20: Monthly basic pay bill | B20: KES/month | C20: =C4+C5+C6 -> 66000 | D20: =D4+D5+D6 -> 66000 | E20: =E4+E5+E6 -> 66000
A21: All-in cost per staff member per month (incl. statutory) | B21: KES/month | C21: =(C10+C11)/36 -> 23700 | D21: =(D10+D11)/36 -> 23700 | E21: =(E10+E11)/36 -> 23700
A22: Minimum people for 7-day cover (1 on site, 5.5-day weeks) | B22: FTE | C22: =365/(5.5*52*(1-3/52)) -> 1.3543599 | D22: =365/(5.5*52*(1-3/52)) -> 1.3543599 | E22: =365/(5.5*52*(1-3/52)) -> 1.3543599
A23: Poultry per staff member | B23: birds | C23: =Poultry!C244/3 -> 756.66667 | D23: =Poultry!D244/3 -> 756.66667 | E23: =Poultry!E244/3 -> 756.66667
A24: Hired labour as % of revenue | B24: % | C24: =C19/Farm_PnL!C15 -> 0.28057559 | D24: =D19/Farm_PnL!D15 -> 0.178858 | E24: =E19/Farm_PnL!E15 -> 0.12373749
A25: Hired labour as % of gross margin | B25: % | C25: =IF(Farm_PnL!C30<=0,"GM<=0",C19/Farm_PnL!C30) -> GM<=0 | D25: =IF(Farm_PnL!D30<=0,"GM<=0",D19/Farm_PnL!D30) -> 1.0603001 | E25: =IF(Farm_PnL!E30<=0,"GM<=0",E19/Farm_PnL!E30) -> 0.24104572
A26: Gross margin covers labour + vet fees + fixed costs? (GM / total) | B26: x | C26: =Farm_PnL!C30/Farm_PnL!C44 -> -0.6036701 | D26: =Farm_PnL!D30/Farm_PnL!D44 -> 0.34819408 | E26: =Farm_PnL!E30/Farm_PnL!E44 -> 1.7945306

Sheet Lorry
A1: Lorry (annual, KES). All cells are live formulas from Inputs.
A2: Line | B2: Unit | C2: Low (adverse) | D2: Base | E2: High (favourable) | F2: Base in USD | G2: Note
A3: Standing costs (incurred whether or not the lorry moves)
A4: Lorry value | B4: KES | C4: =Inputs!C273 -> 4500000 | D4: =Inputs!D273 -> 4500000 | E4: =Inputs!E273 -> 4500000 | F4: =D4/Inputs!$D$4 -> 34644.699
A5: Depreciation ((value - residual) / life) | B5: KES | C5: =Inputs!C273*(1-Inputs!C274)/Inputs!C275 -> 421875 | D5: =Inputs!D273*(1-Inputs!D274)/Inputs!D275 -> 337500 | E5: =Inputs!E273*(1-Inputs!E274)/Inputs!E275 -> 281250 | F5: =D5/Inputs!$D$4 -> 2598.3525 | G5: Non-cash, but the real cost of ownership
A6: Comprehensive insurance | B6: KES | C6: =Inputs!C273*Inputs!C276 -> 225000 | D6: =Inputs!D273*Inputs!D276 -> 180000 | E6: =Inputs!E273*Inputs!E276 -> 135000 | F6: =D6/Inputs!$D$4 -> 1385.788
A7: NTSA annual inspection | B7: KES | C7: =Inputs!C277 -> 4600 | D7: =Inputs!D277 -> 4600 | E7: =Inputs!E277 -> 4600 | F7: =D7/Inputs!$D$4 -> 35.414582
A8: Licence, governor, GPS tracker, driver licence upkeep | B8: KES | C8: =Inputs!C278 -> 40000 | D8: =Inputs!D278 -> 30000 | E8: =Inputs!E278 -> 25000 | F8: =D8/Inputs!$D$4 -> 230.96466
A9: Fixed maintenance | B9: KES | C9: =Inputs!C273*Inputs!C279 -> 135000 | D9: =Inputs!D273*Inputs!D279 -> 90000 | E9: =Inputs!E273*Inputs!E279 -> 67500 | F9: =D9/Inputs!$D$4 -> 692.89399
A10: Standing cash costs | B10: KES | C10: =C6+C7+C8+C9 -> 404600 | D10: =D6+D7+D8+D9 -> 304600 | E10: =E6+E7+E8+E9 -> 232100 | F10: =D10/Inputs!$D$4 -> 2345.0612
A11: Standing cost incl. depreciation | B11: KES | C11: =C10+C5 -> 826475 | D11: =D10+D5 -> 642100 | E11: =E10+E5 -> 513350 | F11: =D11/Inputs!$D$4 -> 4943.4137
A12: Own-farm use (feed, sales runs)
A13: Fuel | B13: KES | C13: =Inputs!C283/Inputs!C281*Inputs!C282 -> 337500 | D13: =Inputs!D283/Inputs!D281*Inputs!D282 -> 197333.33 | E13: =Inputs!E283/Inputs!E281*Inputs!E282 -> 117272.73 | F13: =D13/Inputs!$D$4 -> 1519.2342
A14: Variable maintenance (tyres, oil, repairs) | B14: KES | C14: =Inputs!C283*Inputs!C280 -> 108000 | D14: =Inputs!D283*Inputs!D280 -> 56000 | E14: =Inputs!E283*Inputs!E280 -> 33000 | F14: =D14/Inputs!$D$4 -> 431.13404
A15: Driver (ad hoc days) | B15: KES | C15: =Inputs!C284*Inputs!C285 -> 140000 | D15: =Inputs!D284*Inputs!D285 -> 78000 | E15: =Inputs!E284*Inputs!E285 -> 48000 | F15: =D15/Inputs!$D$4 -> 600.50812
A16: Own-use running cost | B16: KES | C16: =C13+C14+C15 -> 585500 | D16: =D13+D14+D15 -> 331333.33 | E16: =E13+E14+E15 -> 198272.73 | F16: =D16/Inputs!$D$4 -> 2550.8764
A17: Credit: transport the lorry replaces | B17: KES | C17: =Inputs!C286*Inputs!C267 -> 27500 | D17: =Inputs!D286*Inputs!D267 -> 24000 | E17: =Inputs!E286*Inputs!E267 -> 20000 | F17: =D17/Inputs!$D$4 -> 184.77173
A18: External hire (zero in headline: no source for demand or rates)
A19: Hire days | B19: days | C19: =Inputs!C287 -> 0 | D19: =Inputs!D287 -> 0 | E19: =Inputs!E287 -> 0
A20: Hire revenue | B20: KES | C20: =C19*Inputs!C288 -> 0 | D20: =D19*Inputs!D288 -> 0 | E20: =E19*Inputs!E288 -> 0 | F20: =D20/Inputs!$D$4 -> 0
A21: Hire running cost (fuel, maintenance, driver) | B21: KES | C21: =C19*(Inputs!C289/Inputs!C281*Inputs!C282+Inputs!C289*Inputs!C280+Inputs!C290) -> 0 | D21: =D19*(Inputs!D289/Inputs!D281*Inputs!D282+Inputs!D289*Inputs!D280+Inputs!D290) -> 0 | E21: =E19*(Inputs!E289/Inputs!E281*Inputs!E282+Inputs!E289*Inputs!E280+Inputs!E290) -> 0 | F21: =D21/Inputs!$D$4 -> 0
A22: Net hire contribution | B22: KES | C22: =C20-C21 -> 0 | D22: =D20-D21 -> 0 | E22: =E20-E21 -> 0 | F22: =D22/Inputs!$D$4 -> 0
A23: Net effect on the farm
A24: Net lorry cost to OMBM (standing + running - credit - hire) | B24: KES | C24: =C11+C16-C17-C22 -> 1384475 | D24: =D11+D16-D17-D22 -> 949433.33 | E24: =E11+E16-E17-E22 -> 691622.73 | F24: =D24/Inputs!$D$4 -> 7309.5183
A25: Net lorry cash cost (excl. depreciation) | B25: KES | C25: =C24-C5 -> 962600 | D25: =D24-D5 -> 611933.33 | E25: =E24-E5 -> 410372.73 | F25: =D25/Inputs!$D$4 -> 4711.1659
A26: Net lorry cost as % of poultry+livestock gross margin | B26: % | C26: =IF(Farm_PnL!C30<=0,"GM<=0",C24/Farm_PnL!C30) -> GM<=0 | D26: =IF(Farm_PnL!D30<=0,"GM<=0",D24/Farm_PnL!D30) -> 1.1595073 | E26: =IF(Farm_PnL!E30<=0,"GM<=0",E24/Farm_PnL!E30) -> 0.1925756
A27: Break-even hire (illustrative revenue per day from Inputs)
A28: Net contribution per hire day (revenue - fuel - maintenance - driver) | B28: KES/day | C28: =Inputs!C288-(Inputs!C289/Inputs!C281*Inputs!C282+Inputs!C289*Inputs!C280+Inputs!C290) -> 4362.5 | D28: =Inputs!D288-(Inputs!D289/Inputs!D281*Inputs!D282+Inputs!D289*Inputs!D280+Inputs!D290) -> 13000 | E28: =Inputs!E288-(Inputs!E289/Inputs!E281*Inputs!E282+Inputs!E289*Inputs!E280+Inputs!E290) -> 21986.364
A29: Hire days per year to cover the lorry economically (incl. depreciation) | B29: days | C29: =IF(C28<=0,"never",(C11+C16-C17)/C28) -> 317.35817 | D29: =IF(D28<=0,"never",(D11+D16-D17)/D28) -> 73.033333 | E29: =IF(E28<=0,"never",(E11+E16-E17)/E28) -> 31.456895
A30: Hire days per year to cover cash costs only | B30: days | C30: =IF(C28<=0,"never",(C10+C16-C17)/C28) -> 220.6533 | D30: =IF(D28<=0,"never",(D10+D16-D17)/D28) -> 47.071795 | E30: =IF(E28<=0,"never",(E10+E16-E17)/E28) -> 18.664875
A31: Break-even hire days as % of a 250-day working year | B31: % | C31: =IF(ISNUMBER(C29),C29/250,"n/a") -> 1.2694327 | D31: =IF(ISNUMBER(D29),D29/250,"n/a") -> 0.29213333 | E31: =IF(ISNUMBER(E29),E29/250,"n/a") -> 0.12582758
A32: Net lorry cost to OMBM if hired 0 days a year at illustrative rate | B32: KES | C32: =C11+C16-C17-0*C28 -> 1384475 | D32: =D11+D16-D17-0*D28 -> 949433.33 | E32: =E11+E16-E17-0*E28 -> 691622.73 | F32: =D32/Inputs!$D$4 -> 7309.5183
A33: Net lorry cost to OMBM if hired 25 days a year at illustrative rate | B33: KES | C33: =C11+C16-C17-25*C28 -> 1275412.5 | D33: =D11+D16-D17-25*D28 -> 624433.33 | E33: =E11+E16-E17-25*E28 -> 141963.64 | F33: =D33/Inputs!$D$4 -> 4807.4011
A34: Net lorry cost to OMBM if hired 50 days a year at illustrative rate | B34: KES | C34: =C11+C16-C17-50*C28 -> 1166350 | D34: =D11+D16-D17-50*D28 -> 299433.33 | E34: =E11+E16-E17-50*E28 -> -407695.45 | F34: =D34/Inputs!$D$4 -> 2305.284
A35: Net lorry cost to OMBM if hired 100 days a year at illustrative rate | B35: KES | C35: =C11+C16-C17-100*C28 -> 948225 | D35: =D11+D16-D17-100*D28 -> -350566.67 | E35: =E11+E16-E17-100*E28 -> -1507013.6 | F35: =D35/Inputs!$D$4 -> -2698.9504
A36: Net lorry cost to OMBM if hired 150 days a year at illustrative rate | B36: KES | C36: =C11+C16-C17-150*C28 -> 730100 | D36: =D11+D16-D17-150*D28 -> -1000566.7 | E36: =E11+E16-E17-150*E28 -> -2606331.8 | F36: =D36/Inputs!$D$4 -> -7703.1847
A37: Net lorry cost to OMBM if hired 200 days a year at illustrative rate | B37: KES | C37: =C11+C16-C17-200*C28 -> 511975 | D37: =D11+D16-D17-200*D28 -> -1650566.7 | E37: =E11+E16-E17-200*E28 -> -3705650 | F37: =D37/Inputs!$D$4 -> -12707.419
A38: Sell the lorry instead
A39: Net sale proceeds (after selling cost) | B39: KES | C39: =Inputs!C273*(1-Inputs!C9) -> 4275000 | D39: =Inputs!D273*(1-Inputs!D9) -> 4275000 | E39: =Inputs!E273*(1-Inputs!E9) -> 4275000 | F39: =D39/Inputs!$D$4 -> 32912.464
A40: Return on proceeds at declared real return | B40: KES | C40: =C39*Inputs!C5 -> 85500 | D40: =D39*Inputs!D5 -> 85500 | E40: =E39*Inputs!E5 -> 85500 | F40: =D40/Inputs!$D$4 -> 658.24929
...

Sheet Capital
A1: Capital (annual, KES). All cells are live formulas from Inputs.
A2: Line | B2: Unit | C2: Low (adverse) | D2: Base | E2: High (favourable) | F2: Base in USD | G2: Note
A3: Capital base from owner data (market / replacement values, mostly ASSUMED)
A4: Land: acres x price per acre | B4: KES | C4: =Inputs!C11*Inputs!C12 -> 8050000 | D4: =Inputs!D11*Inputs!D12 -> 11500000 | E4: =Inputs!E11*Inputs!E12 -> 16100000 | F4: =D4/Inputs!$D$4 -> 88536.454 | G4: Owned outright; opportunity cost only
A5: Water pans (sunk; inside land value) | B5: KES | C5: =Inputs!C17 -> 0 | D5: =Inputs!D17 -> 0 | E5: =Inputs!E17 -> 0 | F5: =D5/Inputs!$D$4 -> 0
A6: Farm structures | B6: KES | C6: =Inputs!C13 -> 2000000 | D6: =Inputs!D13 -> 2000000 | E6: =Inputs!E13 -> 2000000 | F6: =D6/Inputs!$D$4 -> 15397.644
A7: Cattle | B7: KES | C7: =Cattle!C19 -> 600000 | D7: =Cattle!D19 -> 600000 | E7: =Cattle!E19 -> 600000 | F7: =D7/Inputs!$D$4 -> 4619.2932
A8: Sheep | B8: KES | C8: =Sheep!C16 -> 300000 | D8: =Sheep!D16 -> 300000 | E8: =Sheep!E16 -> 300000 | F8: =D8/Inputs!$D$4 -> 2309.6466
A9: Goats | B9: KES | C9: =Goats!C16 -> 65000 | D9: =Goats!D16 -> 65000 | E9: =Goats!E16 -> 65000 | F9: =D9/Inputs!$D$4 -> 500.42344
A10: Poultry | B10: KES | C10: =Poultry!C261 -> 1230000 | D10: =Poultry!D261 -> 1230000 | E10: =Poultry!E261 -> 1230000 | F10: =D10/Inputs!$D$4 -> 9469.5512
A11: All animals | B11: KES | C11: =SUM(C7:C10) -> 2195000 | D11: =SUM(D7:D10) -> 2195000 | E11: =SUM(E7:E10) -> 2195000 | F11: =D11/Inputs!$D$4 -> 16898.914
A12: Lorry | B12: KES | C12: =Inputs!C273 -> 4500000 | D12: =Inputs!D273 -> 4500000 | E12: =Inputs!E273 -> 4500000 | F12: =D12/Inputs!$D$4 -> 34644.699
A13: Feed and drug stores on hand | B13: KES | C13: =Inputs!C67/12*(Farm_PnL!C59+Farm_PnL!C61) -> 2055122.4 | D13: =Inputs!D67/12*(Farm_PnL!D59+Farm_PnL!D61) -> 1577155.8 | E13: =Inputs!E67/12*(Farm_PnL!E59+Farm_PnL!E61) -> 1266930.6 | F13: =D13/Inputs!$D$4 -> 12142.242
A14: TOTAL capital (land + pans + structures + animals + lorry + stores) | B14: KES | C14: =C4+C5+C6+C11+C12+C13 -> 18800122 | D14: =D4+D5+D6+D11+D12+D13 -> 21772156 | E14: =E4+E5+E6+E11+E12+E13 -> 26061931 | F14: =D14/Inputs!$D$4 -> 167619.95
A15: Capital excluding land (the operating base) | B15: KES | C15: =C14-C4 -> 10750122 | D15: =D14-D4 -> 10272156 | E15: =E14-E4 -> 9961930.6 | F15: =D15/Inputs!$D$4 -> 79083.5
A16: Capital excluding land and lorry | B16: KES | C16: =C15-C12 -> 6250122.4 | D16: =D15-D12 -> 5772155.8 | E16: =E15-E12 -> 5461930.6 | F16: =D16/Inputs!$D$4 -> 44438.8
A17: Ambiguity test: is KES 2m structures only or total capital?
A18: Land + animals + lorry (everything except structures) | B18: KES | C18: =C4+C11+C12 -> 14745000 | D18: =D4+D11+D12 -> 18195000 | E18: =E4+E11+E12 -> 22795000 | F18: =D18/Inputs!$D$4 -> 140080.07
A19: Could KES 2m be TOTAL capital? | B19: text | C19: =IF(C18>Inputs!C13,"No: land, animals and lorry alone exceed KES 2m","Possible") -> No: land, animals and lorry alone exceed KES 2m | D19: =IF(D18>Inputs!D13,"No: land, animals and lorry alone exceed KES 2m","Possible") -> No: land, animals and lorry alone exceed KES 2m | E19: =IF(E18>Inputs!E13,"No: land, animals and lorry alone exceed KES 2m","Possible") -> No: land, animals and lorry alone exceed KES 2m
A20: Animals alone vs KES 2m | B20: text | C20: =IF(C11>Inputs!C13,"Animals alone exceed KES 2m","Animals below KES 2m") -> Animals alone exceed KES 2m | D20: =IF(D11>Inputs!D13,"Animals alone exceed KES 2m","Animals below KES 2m") -> Animals alone exceed KES 2m | E20: =IF(E11>Inputs!E13,"Animals alone exceed KES 2m","Animals below KES 2m") -> Animals alone exceed KES 2m
A21: Returns
A22: OMBM / capital excluding land | B22: % | C22: =Farm_PnL!C46/C15 -> -0.43547119 | D22: =Farm_PnL!D46/D15 -> -0.14921975 | E22: =Farm_PnL!E46/E15 -> 0.15961887
A23: OMBM / total capital | B23: % | C23: =Farm_PnL!C46/C14 -> -0.24900735 | D23: =Farm_PnL!D46/D14 -> -0.070402239 | E23: =Farm_PnL!E46/E14 -> 0.061012829
A24: Land as share of total capital | B24: % | C24: =C4/C14 -> 0.4281887 | D24: =D4/D14 -> 0.52819758 | E24: =E4/E14 -> 0.6177593

Sheet Overhead
A1: Control and management overhead: PLAN generic structure vs right-sized for this farm (KES/yr). ASSUMED quotes, unchanged from v1. Blue = editable.
A2: Item | B2: Class | C2: PLAN generic KES/yr | D2: Right-sized KES/yr | E2: Treatment | F2: Generic USD | G2: Right-sized USD | H2: Note
